<robot name="grabby">
    <material name="pistachio_green">
        <color rgba="147.0 166.0 131.0 1.0" />
    </material>
    <material name="black">
        <color rgba="0 0 0 1" />
    </material>
    <material name="green">
        <color rgba="0.0 1.0 0.0 1.0" />
    </material>

    <!-- Base Link -->
    <link name="base_link">
        <visual>
            <geometry>
                <!-- Size: length width height in meters -->
                <box size="0.325 0.28 0.11" />
            </geometry>
            <material name="pistachio_green"/>
        </visual>
        <collision>
            <geometry>
                <box size="0.325 0.28 0.11" />
            </geometry>
        </collision>
    </link>

    <!-- Base footprint -->
    <link name="base_footprint" />

    <joint name="base_footprint_to_base_link" type="fixed">
        <parent link="base_footprint" />
        <child link="base_link" />
        <origin xyz="0 0 0.09" rpy="0 0 0" />
    </joint>

    <!-- Lidar -->
    <link name="laser">
        <visual>
            <geometry>
                <cylinder length="0.055" radius="0.035" />
            </geometry>
            <material name="black" />
        </visual>
        <collision>
            <geometry>
                <cylinder length="0.055" radius="0.035" />
            </geometry>
        </collision>
    </link>

    <joint name="base_link_to_laser" type="fixed">
        <parent link="base_link" />
        <child link="laser" />
        <origin xyz="0.06 0 0.08" rpy="0 0 0" />
        <!-- Use the line below if the LiDAR is pointing backwards (rotates along z of pi) -->
        <!-- <origin xyz="0.06 0 0.08" rpy="0 0 3.1416" /> -->
    </joint>

    <!-- Left Wheel -->
    <link name="left_wheel">
        <visual>
            <geometry>
                <cylinder length="0.025" radius="0.035" /> 
            </geometry>
            <material name="black" />
        </visual>
        <collision>
            <geometry>
                <cylinder length="0.025" radius="0.035" />
            </geometry>
        </collision>
    </link>

    <joint name="base_link_to_left_wheel" type="continuous">
        <parent link="base_link" />
        <child link="left_wheel" />
        <origin xyz="0 -0.09 0.022" rpy="0 0 0" />
        <axis xyz="0 1 0" />
    </joint>

    <!-- Right Wheel -->
    <link name="right_wheel">
        <visual>
            <geometry>
                <cylinder length="0.025" radius="0.035" />
            </geometry>
            <material name="black" />
        </visual>
        <collision>
            <geometry>
                <cylinder length="0.025" radius="0.035" />
            </geometry>
        </collision>
    </link>

    <joint name="base_link_to_right_wheel" type="continuous">
        <parent link="base_link" />
        <child link="right_wheel" />
        <origin xyz="0 0.09 0.022" rpy="0 0 0" /> 
        <axis xyz="0 1 0" />
    </joint>

    <!-- IMU -->
    <link name="imu">
        <visual>
            <geometry>
                <box size="0.0208 0.0157 0.0016" /> 
            </geometry>
            <material name="green" />
        </visual>
        <collision>
            <geometry>
                <box size="0.0208 0.0157 0.0016" />
            </geometry>
        </collision>
    </link>

    <joint name="base_link_to_imu" type="fixed">
        <parent link="base_link" />
        <child link="imu" />
        <origin xyz="0.1175 0.095 -0.045" rpy="0 0 0" />  
</robot>